Workbook

Sheet Raw_Data
A1: Order_ID | B1: Order_Date | C1: Customer_ID | D1: Product | E1: Category | F1: Region | G1: Quantity | H1: Unit_Price | I1: Discount | J1: Revenue | K1: Cost | L1: Profit | M1: Order_Status | N1: Expected_Revenue | O1: New_profit
A2: ORD0088 | B2: 46007 | C2: CUST0075 | D2: Wireless Mouse | E2: Electronics | F2: South | G2: 1 | H2: 9.3 | I2: 0 | J2: 9.3 | K2: 6.13 | L2: 3.17 | M2: Returned | N2: =IF(ABS(ROUND(G2*H2*(1-I2),2)-J2)<=0.01,"OK","Mismatch") -> OK | O2: =IF(ROUND(J2-K2,2)=ROUND(L2,2),"OK","Mismatch") -> OK | Q2: =COUNTIFS(I2:I503,">100") -> 0 | R2: =COUNTIFS(I2:I503,">1") -> 1
A3: ORD0088 | B3: 46007 | C3: CUST0075 | D3: Wireless Mouse | E3: Electronics | F3: South | G3: 1 | H3: 9.3 | I3: 0 | J3: 9.3 | K3: 6.13 | L3: 3.17 | M3: Returned | N3: =IF(ABS(ROUND(G3*H3*(1-I3),2)-J3)<=0.01,"OK","Mismatch") -> OK | O3: =IF(ROUND(J3-K3,2)=ROUND(L3,2),"OK","Mismatch") -> OK
A4: ORD0212 | B4: 45875 | C4: CUST0102 | D4: Backpack | E4: Accessories | F4: South | G4: 1 | H4: 10.72 | I4: 0 | J4: 10.72 | K4: 8.53 | L4: 2.19 | M4: Returned | N4: =IF(ABS(ROUND(G4*H4*(1-I4),2)-J4)<=0.01,"OK","Mismatch") -> OK | O4: =IF(ROUND(J4-K4,2)=ROUND(L4,2),"OK","Mismatch") -> OK | Q4: =COUNTIF(I2:I503,"<0") -> 0 | R4: =MAX(I2:I503) -> 1.25
A5: ORD0194 | B5: 45658 | C5: CUST0147 | D5: Planner | E5: Stationery | F5: East | G5: 1 | H5: 13.23 | I5: 0.15 | J5: 11.25 | K5: 8.51 | L5: 2.74 | M5: Completed | N5: =IF(ABS(ROUND(G5*H5*(1-I5),2)-J5)<=0.01,"OK","Mismatch") -> OK | O5: =IF(ROUND(J5-K5,2)=ROUND(L5,2),"OK","Mismatch") -> OK
A6: ORD0054 | B6: 45941 | C6: CUST0128 | D6: Laptop Sleeve | E6: Accessories | F6: West | G6: 1 | H6: 17.2 | I6: 0.2 | J6: 13.76 | K6: 11.07 | L6: 2.69 | M6: Completed | N6: =IF(ABS(ROUND(G6*H6*(1-I6),2)-J6)<=0.01,"OK","Mismatch") -> OK | O6: =IF(ROUND(J6-K6,2)=ROUND(L6,2),"OK","Mismatch") -> OK
A7: ORD0296 | B7: 45782 | C7: CUST0110 | D7: Headphones | E7: Electronics | F7: South | G7: 1 | H7: 16.28 | I7: 0.15 | J7: 13.84 | K7: 11.15 | L7: 2.69 | M7: Completed | N7: =IF(ABS(ROUND(G7*H7*(1-I7),2)-J7)<=0.01,"OK","Mismatch") -> OK | O7: =IF(ROUND(J7-K7,2)=ROUND(L7,2),"OK","Mismatch") -> OK
A8: ORD0411 | B8: 45794 | C8: CUST0164 | D8: Storage Box | E8: Home | F8: East | G8: 1 | H8: 16.68 | I8: 0.1 | J8: 15.01 | K8: 9.99 | L8: 5.02 | M8: Completed | N8: =IF(ABS(ROUND(G8*H8*(1-I8),2)-J8)<=0.01,"OK","Mismatch") -> OK | O8: =IF(ROUND(J8-K8,2)=ROUND(L8,2),"OK","Mismatch") -> OK
A9: ORD0173 | B9: 46005 | C9: CUST0062 | D9: Keyboard | E9: Electronics | F9: West | G9: 1 | H9: 16.94 | I9: 0.05 | J9: 16.09 | K9: 12.27 | L9: 3.82 | M9: Completed | N9: =IF(ABS(ROUND(G9*H9*(1-I9),2)-J9)<=0.01,"OK","Mismatch") -> OK | O9: =IF(ROUND(J9-K9,2)=ROUND(L9,2),"OK","Mismatch") -> OK
A10: ORD0315 | B10: 45756 | C10: CUST0173 | D10: Backpack | E10: Accessories | F10: East | G10: 1 | H10: 19.59 | I10: 0.05 | J10: 18.61 | K10: 14.99 | L10: 3.62 | M10: Returned | N10: =IF(ABS(ROUND(G10*H10*(1-I10),2)-J10)<=0.01,"OK","Mismatch") -> OK | O10: =IF(ROUND(J10-K10,2)=ROUND(L10,2),"OK","Mismatch") -> OK
A11: ORD0495 | B11: 45865 | C11: CUST0114 | D11: Cable Organizer | E11: Accessories | F11: West | G11: 1 | H11: 23.31 | I11: 0.2 | J11: 18.65 | K11: 13.28 | L11: 5.37 | M11: Returned | N11: =IF(ABS(ROUND(G11*H11*(1-I11),2)-J11)<=0.01,"OK","Mismatch") -> OK | O11: =IF(ROUND(J11-K11,2)=ROUND(L11,2),"OK","Mismatch") -> OK
A12: ORD0119 | B12: 45769 | C12: CUST0125 | D12: Cable Organizer | E12: Accessories | F12: East | G12: 2 | H12: 10.24 | I12: 0 | J12: 20.48 | K12: 12.54 | L12: 7.94 | M12: Completed | N12: =IF(ABS(ROUND(G12*H12*(1-I12),2)-J12)<=0.01,"OK","Mismatch") -> OK | O12: =IF(ROUND(J12-K12,2)=ROUND(L12,2),"OK","Mismatch") -> OK
A13: ORD0089 | B13: 45880 | C13: CUST0006 | D13: Storage Box | E13: Home | F13: South | G13: 1 | H13: 21.8 | I13: 0.05 | J13: 20.71 | K13: 13.94 | L13: 6.77 | M13: Returned | N13: =IF(ABS(ROUND(G13*H13*(1-I13),2)-J13)<=0.01,"OK","Mismatch") -> OK | O13: =IF(ROUND(J13-K13,2)=ROUND(L13,2),"OK","Mismatch") -> OK
A14: ORD0351 | B14: 45758 | C14: CUST0048 | D14: Backpack | E14: Accessories | F14: East | G14: 1 | H14: 26.12 | I14: 0.1 | J14: 23.51 | K14: 17.47 | L14: 6.04 | M14: Completed | N14: =IF(ABS(ROUND(G14*H14*(1-I14),2)-J14)<=0.01,"OK","Mismatch") -> OK | O14: =IF(ROUND(J14-K14,2)=ROUND(L14,2),"OK","Mismatch") -> OK
A15: ORD0072 | B15: 45945 | C15: CUST0034 | D15: Keyboard | E15: Electronics | F15: West | G15: 1 | H15: 30.22 | I15: 0.2 | J15: 24.18 | K15: 17.7 | L15: 6.48 | M15: Completed | N15: =IF(ABS(ROUND(G15*H15*(1-I15),2)-J15)<=0.01,"OK","Mismatch") -> OK | O15: =IF(ROUND(J15-K15,2)=ROUND(L15,2),"OK","Mismatch") -> OK
A16: ORD0277 | B16: 45884 | C16: CUST0006 | D16: Phone Stand | E16: Accessories | F16: East | G16: 1 | H16: 24.19 | I16: 0 | J16: 24.19 | K16: 15.35 | L16: 8.84 | M16: Completed | N16: =IF(ABS(ROUND(G16*H16*(1-I16),2)-J16)<=0.01,"OK","Mismatch") -> OK | O16: =IF(ROUND(J16-K16,2)=ROUND(L16,2),"OK","Mismatch") -> OK
... A19: ORD0370 | B19: 45727 | C19: CUST0169 | D19: Cable Organizer | E19: Accessories | F19: West | G19: 1 | H19: 31.56 | I19: 0.2 | J19: 25.25 | K19: 17.88 | L19: 7.37 | M19: Returned | N19: =IF(ABS(ROUND(G19*H19*(1-I19),2)-J19)<=0.01,"OK","Mismatch") -> OK | O19: =IF(ROUND(J19-K19,2)=ROUND(L19,2),"OK","Mismatch") -> OK
A20: ORD0320 | B20: 45724 | D20: Pen Set | E20: Stationery | F20: North | G20: 1 | H20: 26.1 | I20: 0 | J20: 26.1 | K20: 21.97 | L20: 4.13 | M20: Completed | N20: =IF(ABS(ROUND(G20*H20*(1-I20),2)-J20)<=0.01,"OK","Mismatch") -> OK | O20: =IF(ROUND(J20-K20,2)=ROUND(L20,2),"OK","Mismatch") -> OK
A21: ORD0018 | B21: 45882 | C21: CUST0051 | D21: Wireless Mouse | E21: Electronics | F21: South | G21: 3 | H21: 9.2 | I21: 0.05 | J21: 26.22 | K21: 17.7 | L21: 8.52 | M21: Cancelled | N21: =IF(ABS(ROUND(G21*H21*(1-I21),2)-J21)<=0.01,"OK","Mismatch") -> OK | O21: =IF(ROUND(J21-K21,2)=ROUND(L21,2),"OK","Mismatch") -> OK
A22: ORD0182 | B22: 45671 | C22: CUST0078 | D22: Headphones | E22: Electronics | F22: South | G22: 1 | H22: 30.63 | I22: 0.1 | J22: 27.57 | K22: 22.68 | L22: 4.89 | M22: Completed | N22: =IF(ABS(ROUND(G22*H22*(1-I22),2)-J22)<=0.01,"OK","Mismatch") -> OK | O22: =IF(ROUND(J22-K22,2)=ROUND(L22,2),"OK","Mismatch") -> OK
A23: ORD0482 | B23: 45862 | C23: CUST0081 | D23: Phone Stand | E23: Accessories | F23: South | G23: 4 | H23: 8.11 | I23: 0.15 | J23: 27.57 | K23: 21.72 | L23: 5.85 | M23: Returned | N23: =IF(ABS(ROUND(G23*H23*(1-I23),2)-J23)<=0.01,"OK","Mismatch") -> OK | O23: =IF(ROUND(J23-K23,2)=ROUND(L23,2),"OK","Mismatch") -> OK
A24: ORD0333 | B24: 45720 | C24: CUST0038 | D24: USB Hub | E24: Electronics | F24: East | G24: 4 | H24: 8.54 | I24: 0.1 | J24: 30.74 | K24: 19.66 | L24: 11.08 | M24: Completed | N24: =IF(ABS(ROUND(G24*H24*(1-I24),2)-J24)<=0.01,"OK","Mismatch") -> OK | O24: =IF(ROUND(J24-K24,2)=ROUND(L24,2),"OK","Mismatch") -> OK
A25: ORD0112 | B25: 45720 | C25: CUST0104 | D25: Desk Lamp | E25: Home | F25: North | G25: 1 | H25: 38.62 | I25: 0.2 | J25: 30.9 | K25: 18.37 | L25: 12.53 | M25: Returned | N25: =IF(ABS(ROUND(G25*H25*(1-I25),2)-J25)<=0.01,"OK","Mismatch") -> OK | O25: =IF(ROUND(J25-K25,2)=ROUND(L25,2),"OK","Mismatch") -> OK
A26: ORD0023 | B26: 45805 | C26: CUST0164 | D26: Sticky Notes | E26: Stationery | F26: East | G26: 1 | H26: 33.92 | I26: 0.05 | J26: 32.22 | K26: 24.45 | L26: 7.77 | M26: Completed | N26: =IF(ABS(ROUND(G26*H26*(1-I26),2)-J26)<=0.01,"OK","Mismatch") -> OK | O26: =IF(ROUND(J26-K26,2)=ROUND(L26,2),"OK","Mismatch") -> OK
A27: ORD0381 | B27: 45725 | C27: CUST0139 | D27: Keyboard | E27: Electronics | F27: West | G27: 1 | H27: 38.14 | I27: 0.15 | J27: 32.42 | K27: 20.58 | L27: 11.84 | M27: Cancelled | N27: =IF(ABS(ROUND(G27*H27*(1-I27),2)-J27)<=0.01,"OK","Mismatch") -> OK | O27: =IF(ROUND(J27-K27,2)=ROUND(L27,2),"OK","Mismatch") -> OK
A28: ORD0161 | B28: 45945 | C28: CUST0130 | D28: Backpack | E28: Accessories | F28: East | G28: 1 | H28: 36.14 | I28: 0.1 | J28: 32.53 | K28: 24.66 | L28: 7.87 | M28: Returned | N28: =IF(ABS(ROUND(G28*H28*(1-I28),2)-J28)<=0.01,"OK","Mismatch") -> OK | O28: =IF(ROUND(J28-K28,2)=ROUND(L28,2),"OK","Mismatch") -> OK
A29: ORD0132 | B29: 45932 | C29: CUST0101 | D29: Phone Stand | E29: Accessories | F29: West | G29: 5 | H29: 8.4 | I29: 0.2 | J29: 33.6 | K29: 18.53 | L29: 15.07 | M29: Returned | N29: =IF(ABS(ROUND(G29*H29*(1-I29),2)-J29)<=0.01,"OK","Mismatch") -> OK | O29: =IF(ROUND(J29-K29,2)=ROUND(L29,2),"OK","Mismatch") -> OK
A30: ORD0377 | B30: 45691 | C30: CUST0129 | D30: Cable Organizer | E30: Accessories | F30: West | G30: 5 | H30: 8.08 | I30: 0.15 | J30: 34.34 | K30: 20.47 | L30: 13.87 | M30: Completed | N30: =IF(ABS(ROUND(G30*H30*(1-I30),2)-J30)<=0.01,"OK","Mismatch") -> OK | O30: =IF(ROUND(J30-K30,2)=ROUND(L30,2),"OK","Mismatch") -> OK
A31: ORD0175 | B31: 45744 | C31: CUST0012 | D31: Laptop Sleeve | E31: Accessories | F31: North | G31: 1 | H31: 36.21 | I31: 0.05 | J31: 34.4 | K31: 26.4 | L31: 8 | M31: Returned | N31: =IF(ABS(ROUND(G31*H31*(1-I31),2)-J31)<=0.01,"OK","Mismatch") -> OK | O31: =IF(ROUND(J31-K31,2)=ROUND(L31,2),"OK","Mismatch") -> OK
A32: ORD0399 | B32: 45970 | C32: CUST0072 | D32: Phone Stand | E32: Accessories | F32: East | G32: 1 | H32: 35.05 | I32: 0 | J32: 35.05 | K32: 22.33 | L32: 12.72 | M32: Completed | N32: =IF(ABS(ROUND(G32*H32*(1-I32),2)-J32)<=0.01,"OK","Mismatch") -> OK | O32: =IF(ROUND(J32-K32,2)=ROUND(L32,2),"OK","Mismatch") -> OK
... A52: ORD0465 | B52: 45773 | C52: CUST0144 | D52: Phone Stand | E52: Accessories | F52: South | G52: 4 | H52: 13.46 | I52: 0.05 | J52: 51.15 | K52: 29.43 | L52: 21.72 | M52: Returned | N52: =IF(ABS(ROUND(G52*H52*(1-I52),2)-J52)<=0.01,"OK","Mismatch") -> OK | O52: =IF(ROUND(J52-K52,2)=ROUND(L52,2),"OK","Mismatch") -> OK
A53: ORD0294 | B53: 45777 | C53: CUST0166 | D53: Headphones | E53: Electronics | F53: North | G53: 1 | H53: 60.42 | I53: 0.15 | J53: 51.36 | K53: 32.59 | L53: 18.77 | M53: Returned | N53: =IF(ABS(ROUND(G53*H53*(1-I53),2)-J53)<=0.01,"OK","Mismatch") -> OK | O53: =IF(ROUND(J53-K53,2)=ROUND(L53,2),"OK","Mismatch") -> OK | P53: = max
A54: ORD0231 | B54: 45664 | C54: CUST0155 | D54: Pen Set | E54: Stationery | F54: West | G54: 2 | H54: 30.48 | I54: 0.15 | J54: 51.82 | K54: 35.49 | L54: 16.33 | M54: Cancelled | N54: =IF(ABS(ROUND(G54*H54*(1-I54),2)-J54)<=0.01,"OK","Mismatch") -> OK | O54: =IF(ROUND(J54-K54,2)=ROUND(L54,2),"OK","Mismatch") -> OK
A55: ORD0114 | B55: 45770 | C55: CUST0114 | D55: Water Bottle | E55: Home | F55: South | G55: 3 | H55: 19.3 | I55: 0.1 | J55: 52.11 | K55: 35.75 | L55: 16.36 | M55: Completed | N55: =IF(ABS(ROUND(G55*H55*(1-I55),2)-J55)<=0.01,"OK","Mismatch") -> OK | O55: =IF(ROUND(J55-K55,2)=ROUND(L55,2),"OK","Mismatch") -> OK
A56: ORD0405 | B56: 45876 | C56: CUST0177 | D56: Keyboard | E56: Electronics | F56: West | G56: 2 | H56: 27.49 | I56: 0.05 | J56: 52.23 | K56: 40.29 | L56: 11.94 | M56: Completed | N56: =IF(ABS(ROUND(G56*H56*(1-I56),2)-J56)<=0.01,"OK","Mismatch") -> OK | O56: =IF(ROUND(J56-K56,2)=ROUND(L56,2),"OK","Mismatch") -> OK
A57: ORD0329 | B57: 45841 | C57: CUST0020 | D57: Desk Lamp | E57: Home | F57: North | G57: 4 | H57: 14.53 | I57: 0.1 | J57: 52.31 | K57: 37.39 | L57: 14.92 | M57: Cancelled | N57: =IF(ABS(ROUND(G57*H57*(1-I57),2)-J57)<=0.01,"OK","Mismatch") -> OK | O57: =IF(ROUND(J57-K57,2)=ROUND(L57,2),"OK","Mismatch") -> OK
A58: ORD0477 | B58: 46022 | C58: CUST0081 | D58: Cable Organizer | E58: Accessories | F58: North | G58: 2 | H58: 29.2 | I58: 0.1 | J58: 52.56 | K58: 35.47 | L58: 17.09 | M58: Cancelled | N58: =IF(ABS(ROUND(G58*H58*(1-I58),2)-J58)<=0.01,"OK","Mismatch") -> OK | O58: =IF(ROUND(J58-K58,2)=ROUND(L58,2),"OK","Mismatch") -> OK
A59: ORD0498 | B59: 45701 | C59: CUST0026 | D59: Phone Stand | E59: Accessories | F59: East | G59: 3 | H59: 17.56 | I59: 0 | J59: 52.68 | K59: 32.33 | L59: 20.35 | M59: Cancelled | N59: =IF(ABS(ROUND(G59*H59*(1-I59),2)-J59)<=0.01,"OK","Mismatch") -> OK | O59: =IF(ROUND(J59-K59,2)=ROUND(L59,2),"OK","Mismatch") -> OK
A60: ORD0242 | B60: 45706 | C60: CUST0036 | D60: Sticky Notes | E60: Stationery | F60: South | G60: 1 | H60: 58.82 | I60: 0.1 | J60: 52.94 | K60: 39.04 | L60: 13.9 | M60: Completed | N60: =IF(ABS(ROUND(G60*H60*(1-I60),2)-J60)<=0.01,"OK","Mismatch") -> OK | O60: =IF(ROUND(J60-K60,2)=ROUND(L60,2),"OK","Mismatch") -> OK
A61: ORD0242 | B61: 45706 | C61: CUST0036 | D61: Sticky Notes | E61: Stationery | F61: South | G61: 1 | H61: 58.82 | I61: 0.1 | J61: 52.94 | K61: 39.04 | L61: 13.9 | M61: Completed | N61: =IF(ABS(ROUND(G61*H61*(1-I61),2)-J61)<=0.01,"OK","Mismatch") -> OK | O61: =IF(ROUND(J61-K61,2)=ROUND(L61,2),"OK","Mismatch") -> OK
...

Sheet Field_Guide
A1: Field | B1: Description
A2: Order_ID | B2: Unique order identifier
A3: Order_Date | B3: Date the order was placed
A4: Customer_ID | B4: Customer identifier
A5: Product | B5: Product purchased
A6: Category | B6: Product category
A7: Region | B7: Customer/order region
A8: Quantity | B8: Number of units ordered
A9: Unit_Price | B9: Price per unit before discount
A10: Discount | B10: Discount applied as a decimal
A11: Revenue | B11: Recorded revenue for the order
A12: Cost | B12: Recorded cost associated with the order
... A14: Order_Status | B14: Current order status

Sheet Cleaned_Data
A1: Order_ID | B1: Order_Date | C1: Customer_ID | D1: Product | E1: Category | F1: Region | G1: Quantity | H1: Unit_Price | I1: Discount | J1: Revenue | K1: Cost | L1: Profit | M1: Order_Status | N1: Expected_Revenue | O1: New_profit | P1: Analysis_Date | Q1: Year_Month
A2: ORD0088 | B2: 46007 | C2: CUST0075 | D2: Wireless Mouse | E2: Electronics | F2: South | G2: 1 | H2: 9.3 | I2: 0 | J2: 9.3 | K2: 6.13 | L2: 3.17 | M2: Returned | N2: OK | O2: OK | P2: =IF(ISNUMBER(B2),INT(B2),"") -> 46007 | Q2: =IF(ISNUMBER(B2),TEXT(B2,"yyyy-mm"),"Invalid/Missing") -> 2025-12 | Y2: Discount | Z2: Group
A3: ORD0212 | B3: 45875 | C3: CUST0102 | D3: Backpack | E3: Accessories | F3: South | G3: 1 | H3: 10.72 | I3: 0 | J3: 10.72 | K3: 8.53 | L3: 2.19 | M3: Returned | N3: OK | O3: OK | P3: =IF(ISNUMBER(B3),INT(B3),"") -> 45875 | Q3: =IF(ISNUMBER(B3),TEXT(B3,"yyyy-mm"),"Invalid/Missing") -> 2025-08 | Y3: 0 | Z3: No Discount
A4: ORD0194 | B4: 45658 | C4: CUST0147 | D4: Planner | E4: Stationery | F4: East | G4: 1 | H4: 13.23 | I4: 0.15 | J4: 11.25 | K4: 8.51 | L4: 2.74 | M4: Completed | N4: OK | O4: OK | P4: =IF(ISNUMBER(B4),INT(B4),"") -> 45658 | Q4: =IF(ISNUMBER(B4),TEXT(B4,"yyyy-mm"),"Invalid/Missing") -> 2025-01 | Y4: 0.05 | Z4: Low Discount
A5: ORD0054 | B5: 45941 | C5: CUST0128 | D5: Laptop Sleeve | E5: Accessories | F5: West | G5: 1 | H5: 17.2 | I5: 0.2 | J5: 13.76 | K5: 11.07 | L5: 2.69 | M5: Completed | N5: OK | O5: OK | P5: =IF(ISNUMBER(B5),INT(B5),"") -> 45941 | Q5: =IF(ISNUMBER(B5),TEXT(B5,"yyyy-mm"),"Invalid/Missing") -> 2025-10 | Y5: 0.1 | Z5: Medium Discount
A6: ORD0296 | B6: 45782 | C6: CUST0110 | D6: Headphones | E6: Electronics | F6: South | G6: 1 | H6: 16.28 | I6: 0.15 | J6: 13.84 | K6: 11.15 | L6: 2.69 | M6: Completed | N6: OK | O6: OK | P6: =IF(ISNUMBER(B6),INT(B6),"") -> 45782 | Q6: =IF(ISNUMBER(B6),TEXT(B6,"yyyy-mm"),"Invalid/Missing") -> 2025-05 | S6: Product | T6: Orders | U6: Revenue | V6: Quantity | W6: AOV | Y6: 0.15 | Z6: High Discount
A7: ORD0411 | B7: 45794 | C7: CUST0164 | D7: Storage Box | E7: Home | F7: East | G7: 1 | H7: 16.68 | I7: 0.1 | J7: 15.01 | K7: 9.99 | L7: 5.02 | M7: Completed | N7: OK | O7: OK | P7: =IF(ISNUMBER(B7),INT(B7),"") -> 45794 | Q7: =IF(ISNUMBER(B7),TEXT(B7,"yyyy-mm"),"Invalid/Missing") -> 2025-05 | S7: Backpack | T7: =COUNTIF(D2:D500,"Backpack") -> 40 | U7: =SUMIF(D2:D500,"Backpack",J2:J500) -> 11205.22 | V7: =SUMIF(D2:D500,"Backpack",G2:G500) -> 124 | W7: =U7/T7 -> 280.1305 | Y7: 0.2 | Z7: Very High Discount
A8: ORD0173 | B8: 46005 | C8: CUST0062 | D8: Keyboard | E8: Electronics | F8: West | G8: 1 | H8: 16.94 | I8: 0.05 | J8: 16.09 | K8: 12.27 | L8: 3.82 | M8: Completed | N8: OK | O8: OK | P8: =IF(ISNUMBER(B8),INT(B8),"") -> 46005 | Q8: =IF(ISNUMBER(B8),TEXT(B8,"yyyy-mm"),"Invalid/Missing") -> 2025-12 | S8: Keyboard | T8: =COUNTIF(D2:D497,"Keyboard") -> 39 | U8: =SUMIF(D2:D497,"Keyboard",J2:J497) -> 9920.64 | V8: =SUMIF(D2:D497,"Keyboard",G2:G497) -> 109 | W8: =U8/T8 -> 254.37538
A9: ORD0315 | B9: 45756 | C9: CUST0173 | D9: Backpack | E9: Accessories | F9: East | G9: 1 | H9: 19.59 | I9: 0.05 | J9: 18.61 | K9: 14.99 | L9: 3.62 | M9: Returned | N9: OK | O9: OK | P9: =IF(ISNUMBER(B9),INT(B9),"") -> 45756 | Q9: =IF(ISNUMBER(B9),TEXT(B9,"yyyy-mm"),"Invalid/Missing") -> 2025-04 | S9: Wireless Mouse | T9: =COUNTIF(D1:D487,"Wireless Mouse") -> 36 | U9: =SUMIF(D1:D487,"Wireless Mouse",J1:J487) -> 7813.93 | V9: =SUMIF(D1:D487,"Wireless Mouse",G1:G487) -> 107 | W9: =U9/T9 -> 217.05361 | Y9: =SUM(3149.69,3054.34,2967.24,2246,2174.82) -> 13592.09
A10: ORD0495 | B10: 45865 | C10: CUST0114 | D10: Cable Organizer | E10: Accessories | F10: West | G10: 1 | H10: 23.31 | I10: 0.2 | J10: 18.65 | K10: 13.28 | L10: 5.37 | M10: Returned | N10: OK | O10: OK | P10: =IF(ISNUMBER(B10),INT(B10),"") -> 45865 | Q10: =IF(ISNUMBER(B10),TEXT(B10,"yyyy-mm"),"Invalid/Missing") -> 2025-07 | S10: Storage Box | T10: =COUNTIF(D3:D491,"Storage Box") -> 34 | U10: =SUMIF(D3:D491,"Storage Box",J3:J491) -> 9703.07 | V10: =SUMIF(D3:D491,"Storage Box",G3:G491) -> 104 | W10: =U10/T10 -> 285.38441 | Y10: =13592.09/131404.67 -> 0.10343689
A11: ORD0119 | B11: 45769 | C11: CUST0125 | D11: Cable Organizer | E11: Accessories | F11: East | G11: 2 | H11: 10.24 | I11: 0 | J11: 20.48 | K11: 12.54 | L11: 7.94 | M11: Completed | N11: OK | O11: OK | P11: =IF(ISNUMBER(B11),INT(B11),"") -> 45769 | Q11: =IF(ISNUMBER(B11),TEXT(B11,"yyyy-mm"),"Invalid/Missing") -> 2025-04 | S11: Sticky Notes | T11: =COUNTIF(D4:D493,"Sticky Notes") -> 34 | U11: =SUMIF(D4:D493,"Sticky Notes",J4:J493) -> 10459.34 | V11: =SUMIF(D4:D493,"Sticky Notes",G4:G493) -> 101 | W11: =U11/T11 -> 307.62765 | Y11: =38459.01/131404.67 -> 0.29267613
A12: ORD0089 | B12: 45880 | C12: CUST0006 | D12: Storage Box | E12: Home | F12: South | G12: 1 | H12: 21.8 | I12: 0.05 | J12: 20.71 | K12: 13.94 | L12: 6.77 | M12: Returned | N12: OK | O12: OK | P12: =IF(ISNUMBER(B12),INT(B12),"") -> 45880 | Q12: =IF(ISNUMBER(B12),TEXT(B12,"yyyy-mm"),"Invalid/Missing") -> 2025-08 | S12: Laptop Sleeve | T12: =COUNTIF(D2:D500,"Laptop Sleeve") -> 33 | U12: =SUMIF(D2:D500,"Laptop Sleeve",J2:J500) -> 8640.41 | V12: =SUMIF(D2:D500,"Laptop Sleeve",G2:G500) -> 98 | W12: =U12/T12 -> 261.83061
A13: ORD0351 | B13: 45758 | C13: CUST0048 | D13: Backpack | E13: Accessories | F13: East | G13: 1 | H13: 26.12 | I13: 0.1 | J13: 23.51 | K13: 17.47 | L13: 6.04 | M13: Completed | N13: OK | O13: OK | P13: =IF(ISNUMBER(B13),INT(B13),"") -> 45758 | Q13: =IF(ISNUMBER(B13),TEXT(B13,"yyyy-mm"),"Invalid/Missing") -> 2025-04 | S13: Cable Organizer | T13: =COUNTIF(D7:D505,"Cable Organizer") -> 33 | U13: =SUMIF(D7:D505,"Cable Organizer",J7:J505) -> 7977.46 | V13: =SUMIF(D7:D505,"Cable Organizer",G7:G505) -> 94 | W13: =U13/T13 -> 241.74121
A14: ORD0072 | B14: 45945 | C14: CUST0034 | D14: Keyboard | E14: Electronics | F14: West | G14: 1 | H14: 30.22 | I14: 0.2 | J14: 24.18 | K14: 17.7 | L14: 6.48 | M14: Completed | N14: OK | O14: OK | P14: =IF(ISNUMBER(B14),INT(B14),"") -> 45945 | Q14: =IF(ISNUMBER(B14),TEXT(B14,"yyyy-mm"),"Invalid/Missing") -> 2025-10 | S14: Notebook | T14: =COUNTIF(D6:D501,"Notebook") -> 32 | U14: =SUMIF(D6:D501,"Notebook",J6:J501) -> 10241.47 | V14: =SUMIF(D6:D501,"Notebook",G6:G501) -> 108 | W14: =U14/T14 -> 320.04594
A15: ORD0277 | B15: 45884 | C15: CUST0006 | D15: Phone Stand | E15: Accessories | F15: East | G15: 1 | H15: 24.19 | I15: 0 | J15: 24.19 | K15: 15.35 | L15: 8.84 | M15: Completed | N15: OK | O15: OK | P15: =IF(ISNUMBER(B15),INT(B15),"") -> 45884 | Q15: =IF(ISNUMBER(B15),TEXT(B15,"yyyy-mm"),"Invalid/Missing") -> 2025-08 | S15: Pen Set | T15: =COUNTIF(D4:D500,"Pen set") -> 31 | U15: =SUMIF(D4:D500,"Pen Set",J4:J500) -> 7263.44 | V15: =SUMIF(D4:D500,"Pen Set",G4:G500) -> 91 | W15: =U15/T15 -> 234.30452
A16: ORD0202 | B16: 45949 | C16: CUST0051 | D16: Wireless Mouse | E16: Electronics | F16: East | G16: 3 | H16: 9.3 | I16: 0.1 | J16: 25.11 | K16: 20.58 | L16: 4.53 | M16: Completed | N16: OK | O16: OK | P16: =IF(ISNUMBER(B16),INT(B16),"") -> 45949 | Q16: =IF(ISNUMBER(B16),TEXT(B16,"yyyy-mm"),"Invalid/Missing") -> 2025-10 | S16: Water Bottle | T16: =COUNTIF(D5:D495,"Water Bottle") -> 30 | U16: =SUMIF(D5:D495,"Water Bottle",J5:J495) -> 7318.51 | V16: =SUMIF(D5:D495,"Water Bottle",G5:G495) -> 90 | W16: =U16/T16 -> 243.95033
A17: ORD0133 | B17: 45975 | C17: CUST0080 | D17: Laptop Sleeve | E17: Accessories | F17: West | G17: 1 | H17: 31.53 | I17: 0.2 | J17: 25.22 | K17: 17.25 | L17: 7.97 | M17: Returned | N17: OK | O17: OK | P17: =IF(ISNUMBER(B17),INT(B17),"") -> 45975 | Q17: =IF(ISNUMBER(B17),TEXT(B17,"yyyy-mm"),"Invalid/Missing") -> 2025-11 | S17: Office Chair | T17: =COUNTIF(D5:D503,"Office Chair") -> 30 | U17: =SUMIF(D5:D503,"Office Chair",J5:J503) -> 7457.14 | V17: =SUMIF(D5:D503,"Office Chair",G5:G503) -> 85 | W17: =U17/T17 -> 248.57133
A18: ORD0370 | B18: 45727 | C18: CUST0169 | D18: Cable Organizer | E18: Accessories | F18: West | G18: 1 | H18: 31.56 | I18: 0.2 | J18: 25.25 | K18: 17.88 | L18: 7.37 | M18: Returned | N18: OK | O18: OK | P18: =IF(ISNUMBER(B18),INT(B18),"") -> 45727 | Q18: =IF(ISNUMBER(B18),TEXT(B18,"yyyy-mm"),"Invalid/Missing") -> 2025-03 | S18: Planner | T18: =COUNTIF(D11:D501,"Planner") -> 28 | U18: =SUMIF(D11:D501,"Planner",J11:J501) -> 5902.85 | V18: =SUMIF(D11:D501,"Planner",G11:G501) -> 84 | W18: =U18/T18 -> 210.81607
A19: ORD0320 | B19: 45724 | D19: Pen Set | E19: Stationery | F19: North | G19: 1 | H19: 26.1 | I19: 0 | J19: 26.1 | K19: 21.97 | L19: 4.13 | M19: Completed | N19: OK | O19: OK | P19: =IF(ISNUMBER(B19),INT(B19),"") -> 45724 | Q19: =IF(ISNUMBER(B19),TEXT(B19,"yyyy-mm"),"Invalid/Missing") -> 2025-03 | S19: Headphones | T19: =COUNTIF(D11:D509,"Headphones") -> 28 | U19: =SUMIF(D11:D509,"Headphones",J11:J509) -> 7219.19 | V19: =SUMIF(D11:D509,"Headphones",G11:G509) -> 82 | W19: =U19/T19 -> 257.82821
A20: ORD0018 | B20: 45882 | C20: CUST0051 | D20: Wireless Mouse | E20: Electronics | F20: South | G20: 3 | H20: 9.2 | I20: 0.05 | J20: 26.22 | K20: 17.7 | L20: 8.52 | M20: Cancelled | N20: OK | O20: OK | P20: =IF(ISNUMBER(B20),INT(B20),"") -> 45882 | Q20: =IF(ISNUMBER(B20),TEXT(B20,"yyyy-mm"),"Invalid/Missing") -> 2025-08 | S20: Phone Stand | T20: =COUNTIF(D12:D504,"Phone stand") -> 27 | U20: =SUMIF(D12:D504,"Phone Stand",J12:J504) -> 6450.81 | V20: =SUMIF(D12:D504,"Phone Stand",G12:G504) -> 79 | W20: =U20/T20 -> 238.91889
A21: ORD0182 | B21: 45671 | C21: CUST0078 | D21: Headphones | E21: Electronics | F21: South | G21: 1 | H21: 30.63 | I21: 0.1 | J21: 27.57 | K21: 22.68 | L21: 4.89 | M21: Completed | N21: OK | O21: OK | P21: =IF(ISNUMBER(B21),INT(B21),"") -> 45671 | Q21: =IF(ISNUMBER(B21),TEXT(B21,"yyyy-mm"),"Invalid/Missing") -> 2025-01 | S21: USB Hub | T21: =COUNTIF(D14:D501,"USB Hub") -> 22 | U21: =SUMIF(D14:D501,"USB Hub",J14:J501) -> 6493.97 | V21: =SUMIF(D14:D501,"USB Hub",G14:G501) -> 76 | W21: =U21/T21 -> 295.18045
A22: ORD0482 | B22: 45862 | C22: CUST0081 | D22: Phone Stand | E22: Accessories | F22: South | G22: 4 | H22: 8.11 | I22: 0.15 | J22: 27.57 | K22: 21.72 | L22: 5.85 | M22: Returned | N22: OK | O22: OK | P22: =IF(ISNUMBER(B22),INT(B22),"") -> 45862 | Q22: =IF(ISNUMBER(B22),TEXT(B22,"yyyy-mm"),"Invalid/Missing") -> 2025-07 | S22: Desk Lamp | T22: =COUNTIF(D16:D513,"Desk Lamp") -> 18 | U22: =SUMIF(D16:D513,"Desk Lamp",J16:J513) -> 5642.39 | V22: =SUMIF(D16:D513,"Desk Lamp",G16:G513) -> 57 | W22: =U22/T22 -> 313.46611
A23: ORD0333 | B23: 45720 | C23: CUST0038 | D23: USB Hub | E23: Electronics | F23: East | G23: 4 | H23: 8.54 | I23: 0.1 | J23: 30.74 | K23: 19.66 | L23: 11.08 | M23: Completed | N23: OK | O23: OK | P23: =IF(ISNUMBER(B23),INT(B23),"") -> 45720 | Q23: =IF(ISNUMBER(B23),TEXT(B23,"yyyy-mm"),"Invalid/Missing") -> 2025-03
A24: ORD0112 | B24: 45720 | C24: CUST0104 | D24: Desk Lamp | E24: Home | F24: North | G24: 1 | H24: 38.62 | I24: 0.2 | J24: 30.9 | K24: 18.37 | L24: 12.53 | M24: Returned | N24: OK | O24: OK | P24: =IF(ISNUMBER(B24),INT(B24),"") -> 45720 | Q24: =IF(ISNUMBER(B24),TEXT(B24,"yyyy-mm"),"Invalid/Missing") -> 2025-03
A25: ORD0023 | B25: 45805 | C25: CUST0164 | D25: Sticky Notes | E25: Stationery | F25: East | G25: 1 | H25: 33.92 | I25: 0.05 | J25: 32.22 | K25: 24.45 | L25: 7.77 | M25: Completed | N25: OK | O25: OK | P25: =IF(ISNUMBER(B25),INT(B25),"") -> 45805 | Q25: =IF(ISNUMBER(B25),TEXT(B25,"yyyy-mm"),"Invalid/Missing") -> 2025-05
A26: ORD0381 | B26: 45725 | C26: CUST0139 | D26: Keyboard | E26: Electronics | F26: West | G26: 1 | H26: 38.14 | I26: 0.15 | J26: 32.42 | K26: 20.58 | L26: 11.84 | M26: Cancelled | N26: OK | O26: OK | P26: =IF(ISNUMBER(B26),INT(B26),"") -> 45725 | Q26: =IF(ISNUMBER(B26),TEXT(B26,"yyyy-mm"),"Invalid/Missing") -> 2025-03
A27: ORD0161 | B27: 45945 | C27: CUST0130 | D27: Backpack | E27: Accessories | F27: East | G27: 1 | H27: 36.14 | I27: 0.1 | J27: 32.53 | K27: 24.66 | L27: 7.87 | M27: Returned | N27: OK | O27: OK | P27: =IF(ISNUMBER(B27),INT(B27),"") -> 45945 | Q27: =IF(ISNUMBER(B27),TEXT(B27,"yyyy-mm"),"Invalid/Missing") -> 2025-10
A28: ORD0132 | B28: 45932 | C28: CUST0101 | D28: Phone Stand | E28: Accessories | F28: West | G28: 5 | H28: 8.4 | I28: 0.2 | J28: 33.6 | K28: 18.53 | L28: 15.07 | M28: Returned | N28: OK | O28: OK | P28: =IF(ISNUMBER(B28),INT(B28),"") -> 45932 | Q28: =IF(ISNUMBER(B28),TEXT(B28,"yyyy-mm"),"Invalid/Missing") -> 2025-10
A29: ORD0377 | B29: 45691 | C29: CUST0129 | D29: Cable Organizer | E29: Accessories | F29: West | G29: 5 | H29: 8.08 | I29: 0.15 | J29: 34.34 | K29: 20.47 | L29: 13.87 | M29: Completed | N29: OK | O29: OK | P29: =IF(ISNUMBER(B29),INT(B29),"") -> 45691 | Q29: =IF(ISNUMBER(B29),TEXT(B29,"yyyy-mm"),"Invalid/Missing") -> 2025-02
A30: ORD0175 | B30: 45744 | C30: CUST0012 | D30: Laptop Sleeve | E30: Accessories | F30: North | G30: 1 | H30: 36.21 | I30: 0.05 | J30: 34.4 | K30: 26.4 | L30: 8 | M30: Returned | N30: OK | O30: OK | P30: =IF(ISNUMBER(B30),INT(B30),"") -> 45744 | Q30: =IF(ISNUMBER(B30),TEXT(B30,"yyyy-mm"),"Invalid/Missing") -> 2025-03
A31: ORD0399 | B31: 45970 | C31: CUST0072 | D31: Phone Stand | E31: Accessories | F31: East | G31: 1 | H31: 35.05 | I31: 0 | J31: 35.05 | K31: 22.33 | L31: 12.72 | M31: Completed | N31: OK | O31: OK | P31: =IF(ISNUMBER(B31),INT(B31),"") -> 45970 | Q31: =IF(ISNUMBER(B31),TEXT(B31,"yyyy-mm"),"Invalid/Missing") -> 2025-11
A32: ORD0217 | B32: 45802 | C32: CUST0144 | D32: Laptop Sleeve | E32: Accessories | F32: West | G32: 1 | H32: 37.32 | I32: 0.05 | J32: 35.45 | K32: 23.99 | L32: 11.46 | M32: Returned | N32: OK | O32: OK | P32: =IF(ISNUMBER(B32),INT(B32),"") -> 45802 | Q32: =IF(ISNUMBER(B32),TEXT(B32,"yyyy-mm"),"Invalid/Missing") -> 2025-05
A33: ORD0082 | B33: 45910 | C33: CUST0180 | D33: Laptop Sleeve | E33: Accessories | F33: East | G33: 5 | H33: 8.45 | I33: 0.15 | J33: 35.91 | K33: 20.66 | L33: 15.25 | M33: Completed | N33: OK | O33: OK | P33: =IF(ISNUMBER(B33),INT(B33),"") -> 45910 | Q33: =IF(ISNUMBER(B33),TEXT(B33,"yyyy-mm"),"Invalid/Missing") -> 2025-09
A34: ORD0032 | B34: 45849 | C34: CUST0049 | D34: Cable Organizer | E34: Accessories | F34: West | G34: 1 | H34: 41.58 | I34: 0.1 | J34: 37.42 | K34: 23.73 | L34: 13.69 | M34: Completed | N34: OK | O34: OK | P34: =IF(ISNUMBER(B34),INT(B34),"") -> 45849 | Q34: =IF(ISNUMBER(B34),TEXT(B34,"yyyy-mm"),"Invalid/Missing") -> 2025-07
... A326: ORD0021 | B326: 45829 | C326: CUST0160 | D326: Pen Set | E326: Stationery | F326: South | G326: 5 | H326: 67.35 | I326: 0.1 | J326: 303.08 | K326: 228.59 | L326: 74.49 | M326: Cancelled | N326: OK | O326: OK | P326: =IF(ISNUMBER(B326),INT(B326),"") -> 45829 | Q326: =IF(ISNUMBER(B326),TEXT(B326,"yyyy-mm"),"Invalid/Missing") -> 2025-06
A327: ORD0035 | B327: 45945 | C327: CUST0175 | D327: Desk Lamp | E327: Home | G327: 2 | H327: 169.02 | I327: 0.1 | J327: 304.24 | K327: 219.36 | L327: 84.88 | M327: Completed | N327: OK | O327: OK | P327: =IF(ISNUMBER(B327),INT(B327),"") -> 45945 | Q327: =IF(ISNUMBER(B327),TEXT(B327,"yyyy-mm"),"Invalid/Missing") -> 2025-10
A328: ORD0059 | B328: 45958 | C328: CUST0132 | D328: Sticky Notes | E328: Stationery | F328: West | G328: 5 | H328: 71.75 | I328: 0.15 | J328: 304.94 | K328: 254.37 | L328: 50.57 | M328: Completed | N328: OK | O328: OK | P328: =IF(ISNUMBER(B328),INT(B328),"") -> 45958 | Q328: =IF(ISNUMBER(B328),TEXT(B328,"yyyy-mm"),"Invalid/Missing") -> 2025-10
A329: ORD0163 | B329: 45715 | C329: CUST0124 | D329: Headphones | E329: Electronics | F329: South | G329: 4 | H329: 76.39 | I329: 0 | J329: 305.56 | K329: 258.26 | L329: 47.3 | M329: Completed | N329: OK | O329: OK | P329: =IF(ISNUMBER(B329),INT(B329),"") -> 45715 | Q329: =IF(ISNUMBER(B329),TEXT(B329,"yyyy-mm"),"Invalid/Missing") -> 2025-02
A330: ORD0383 | B330: 45804 | C330: CUST0112 | D330: Water Bottle | E330: Home | F330: East | G330: 2 | H330: 160.89 | I330: 0.05 | J330: 305.69 | K330: 186.88 | L330: 118.81 | M330: Completed | N330: OK | O330: OK | P330: =IF(ISNUMBER(B330),INT(B330),"") -> 45804 | Q330: =IF(ISNUMBER(B330),TEXT(B330,"yyyy-mm"),"Invalid/Missing") -> 2025-05
A331: ORD0317 | B331: 45824 | C331: CUST0034 | D331: Headphones | E331: Electronics | F331: West | G331: 3 | H331: 108.14 | I331: 0.05 | J331: 308.2 | K331: 225.09 | L331: 83.11 | M331: Returned | N331: OK | O331: OK | P331: =IF(ISNUMBER(B331),INT(B331),"") -> 45824 | Q331: =IF(ISNUMBER(B331),TEXT(B331,"yyyy-mm"),"Invalid/Missing") -> 2025-06
...

Sheet Sheet10
A1: Order_ID | B1: Order_Date | C1: Customer_ID | D1: Product | E1: Category | F1: Region | G1: Quantity | H1: Unit_Price | I1: Discount | J1: Revenue | K1: Cost | L1: Profit | M1: Order_Status | N1: Expected_Revenue | O1: New_profit | P1: Analysis_Date | Q1: Year_Month
A2: ORD0088 | B2: 46007 | C2: CUST0075 | D2: Wireless Mouse | E2: Electronics | F2: South | G2: 1 | H2: 9.3 | I2: 0 | J2: 9.3 | K2: 6.13 | L2: 3.17 | M2: Returned | N2: OK | O2: OK | P2: 46007 | Q2: 2025-12
A3: ORD0151 | B3: 45772 | C3: CUST0067 | D3: USB Hub | E3: Electronics | F3: West | G3: 5 | H3: 178.53 | I3: 0 | J3: 892.65 | K3: 727.4 | L3: 165.25 | M3: Cancelled | N3: OK | O3: OK | P3: 45772 | Q3: 2025-04
A4: ORD0071 | B4: 45859 | C4: CUST0083 | D4: Wireless Mouse | E4: Electronics | F4: North | G4: 5 | H4: 179.42 | I4: 0.1 | J4: 807.39 | K4: 630.33 | L4: 177.06 | M4: Cancelled | N4: OK | O4: OK | P4: 45859 | Q4: 2025-07
A5: ORD0410 | B5: 45905 | C5: CUST0022 | D5: Keyboard | E5: Electronics | F5: West | G5: 5 | H5: 170.49 | I5: 0.1 | J5: 767.2 | K5: 625.19 | L5: 142.01 | M5: Completed | N5: OK | O5: OK | P5: 45905 | Q5: 2025-09
A6: ORD0296 | B6: 45782 | C6: CUST0110 | D6: Headphones | E6: Electronics | F6: South | G6: 1 | H6: 16.28 | I6: 0.15 | J6: 13.84 | K6: 11.15 | L6: 2.69 | M6: Completed | N6: OK | O6: OK | P6: 45782 | Q6: 2025-05
A7: ORD0050 | B7: 45853 | C7: CUST0058 | D7: Keyboard | E7: Electronics | F7: North | G7: 5 | H7: 153.32 | I7: 0 | J7: 766.6 | K7: 608.94 | L7: 157.66 | M7: Completed | N7: OK | O7: OK | P7: 45853 | Q7: 2025-07
A8: ORD0173 | B8: 46005 | C8: CUST0062 | D8: Keyboard | E8: Electronics | F8: West | G8: 1 | H8: 16.94 | I8: 0.05 | J8: 16.09 | K8: 12.27 | L8: 3.82 | M8: Completed | N8: OK | O8: OK | P8: 46005 | Q8: 2025-12
A9: ORD0297 | B9: 45721 | C9: CUST0050 | D9: USB Hub | E9: Electronics | F9: North | G9: 5 | H9: 152.16 | I9: 0 | J9: 760.8 | K9: 516.4 | L9: 244.4 | M9: Completed | N9: OK | O9: OK | P9: 45721 | Q9: 2025-03
A10: ORD0145 | B10: 45875 | C10: CUST0169 | D10: Headphones | E10: Electronics | F10: North | G10: 5 | H10: 150.87 | I10: 0 | J10: 754.35 | K10: 425.52 | L10: 328.83 | M10: Completed | N10: OK | O10: OK | P10: 45875 | Q10: 2025-08
A11: ORD0191 | B11: 45951 | C11: CUST0084 | D11: Keyboard | E11: Electronics | F11: East | G11: 5 | H11: 157.28 | I11: 0.05 | J11: 747.08 | K11: 526.45 | L11: 220.63 | M11: Completed | N11: OK | O11: OK | P11: 45951 | Q11: 2025-10
A12: ORD0486 | B12: 45773 | C12: CUST0143 | D12: Headphones | E12: Electronics | F12: North | G12: 5 | H12: 139.22 | I12: 0 | J12: 696.1 | K12: 517.88 | L12: 178.22 | M12: Completed | N12: OK | O12: OK | P12: 45773 | Q12: 2025-04
A13: ORD0095 | B13: 45733 | C13: CUST0035 | D13: Keyboard | E13: Electronics | F13: North | G13: 4 | H13: 173.98 | I13: 0 | J13: 695.92 | K13: 535.34 | L13: 160.58 | M13: Completed | N13: OK | O13: OK | P13: 45733 | Q13: 2025-03
... A129: ORD0176 | B129: 45776 | C129: CUST0053 | D129: Wireless Mouse | E129: Electronics | F129: East | G129: 3 | H129: 45.7 | I129: 0.2 | J129: 109.68 | K129: 71.41 | L129: 38.27 | M129: Cancelled | N129: OK | O129: OK | P129: 45776 | Q129: 2025-04

Sheet month
A3: Row Labels | B3: Sum of Revenue | D3: AOV
A4: 2025-01 | B4: 8292.42 | C4: =COUNTIFS(Cleaned_Data!$B:$B,">="&DATEVALUE(A4&"-01"),Cleaned_Data!$B:$B,"<"&EDATE(DATEVALUE(A4&"-01"),1)) -> 37 | D4: =B4/C4 -> 224.11946
A5: 2025-02 | B5: 13062.06 | C5: =COUNTIFS(Cleaned_Data!$B:$B,">="&DATEVALUE(A5&"-01"),Cleaned_Data!$B:$B,"<"&EDATE(DATEVALUE(A5&"-01"),1)) -> 46 | D5: =B5/C5 -> 283.95783
A6: 2025-03 | B6: 11317.82 | C6: =COUNTIFS(Cleaned_Data!$B:$B,">="&DATEVALUE(A6&"-01"),Cleaned_Data!$B:$B,"<"&EDATE(DATEVALUE(A6&"-01"),1)) -> 42 | D6: =B6/C6 -> 269.4719
A7: 2025-04 | B7: 14120.43 | C7: =COUNTIFS(Cleaned_Data!$B:$B,">="&DATEVALUE(A7&"-01"),Cleaned_Data!$B:$B,"<"&EDATE(DATEVALUE(A7&"-01"),1)) -> 54 | D7: =B7/C7 -> 261.48944
A8: 2025-05 | B8: 7777.89 | C8: =COUNTIFS(Cleaned_Data!$B:$B,">="&DATEVALUE(A8&"-01"),Cleaned_Data!$B:$B,"<"&EDATE(DATEVALUE(A8&"-01"),1)) -> 33 | D8: =B8/C8 -> 235.69364
A9: 2025-06 | B9: 13413.81 | C9: =COUNTIFS(Cleaned_Data!$B:$B,">="&DATEVALUE(A9&"-01"),Cleaned_Data!$B:$B,"<"&EDATE(DATEVALUE(A9&"-01"),1)) -> 47 | D9: =B9/C9 -> 285.40021
A10: 2025-07 | B10: 7243.97 | C10: =COUNTIFS(Cleaned_Data!$B:$B,">="&DATEVALUE(A10&"-01"),Cleaned_Data!$B:$B,"<"&EDATE(DATEVALUE(A10&"-01"),1)) -> 25 | D10: =B10/C10 -> 289.7588
A11: 2025-08 | B11: 10452.93 | C11: =COUNTIFS(Cleaned_Data!$B:$B,">="&DATEVALUE(A11&"-01"),Cleaned_Data!$B:$B,"<"&EDATE(DATEVALUE(A11&"-01"),1)) -> 43 | D11: =B11/C11 -> 243.0914
A12: 2025-09 | B12: 10120.62 | C12: =COUNTIFS(Cleaned_Data!$B:$B,">="&DATEVALUE(A12&"-01"),Cleaned_Data!$B:$B,"<"&EDATE(DATEVALUE(A12&"-01"),1)) -> 39 | D12: =B12/C12 -> 259.50308
A13: 2025-10 | B13: 10579.1 | C13: =COUNTIFS(Cleaned_Data!$B:$B,">="&DATEVALUE(A13&"-01"),Cleaned_Data!$B:$B,"<"&EDATE(DATEVALUE(A13&"-01"),1)) -> 43 | D13: =B13/C13 -> 246.02558
A14: 2025-11 | B14: 11858.72 | C14: =COUNTIFS(Cleaned_Data!$B:$B,">="&DATEVALUE(A14&"-01"),Cleaned_Data!$B:$B,"<"&EDATE(DATEVALUE(A14&"-01"),1)) -> 45 | D14: =B14/C14 -> 263.52711
A15: 2025-12 | B15: 11829.02 | C15: =COUNTIFS(Cleaned_Data!$B:$B,">="&DATEVALUE(A15&"-01"),Cleaned_Data!$B:$B,"<"&EDATE(DATEVALUE(A15&"-01"),1)) -> 43 | D15: =B15/C15 -> 275.09349
A16: Grand Total | B16: 130068.79 | C16: =SUM(C4:C15) -> 497 | D16: =IFERROR(B16/C16,0) -> 261.70783
A18: Data Note:
B19: Monthly revenue analysis includes 497 transactions with valid dates in 2025. Two additional transactions remain in the cleaned dataset but are excluded from monthly analysis because their dates are invalid or unavailable. Total revenue across all 499 transactions is $131,404.67; monthly revenue totals $130,068.79.

Sheet Category
A3: Row Labels | B3: Sum of Revenue | E3: profit margin
A4: Accessories | B4: 33911.28 | E4: =D4/B4 -> 0
A5: Stationery | B5: 33325.19 | E5: =D5/B5 -> 0
A6: Electronics | B6: 32631.58 | E6: =D6/B6 -> 0
A7: Home | B7: 30983.46 | E7: =D7/B7 -> 0
A8: Home & Living | B8: 553.16 | E8: =D8/B8 -> 0
A9: Grand Total | B9: 131404.67

Sheet Region
A3: Row Labels | B3: Sum of Revenue
A4: North | B4: 37909.91
A5: East | B5: 33865.09
A6: West | B6: 31616.59
A7: South | B7: 27984.06
A8: Grand Total | B8: 131375.65

Sheet Discount
A3: Row Labels | B3: Count of Order_ID | C3: Sum of Revenue | D3: Sum of Profit | E3: profit margin | G3: Discount | H3: Profit Margin
A4: 0 | B4: 168 | C4: 46531.63 | D4: 13508.17 | E4: =D4/B4 -> 80.405774 | G4: 0 | H4: 0.8041
A5: 0.05 | B5: 100 | C5: 25255.11 | D5: 7702.66 | E5: =D5/B5 -> 77.0266 | G5: 0.05 | H5: 0.7703
A6: 0.1 | B6: 123 | C6: 32864.31 | D6: 9316.27 | E6: =D6/B6 -> 75.742033 | G6: 0.1 | H6: 0.7574
A7: 0.15 | B7: 75 | C7: 18769.09 | D7: 5538.8 | E7: =D7/B7 -> 73.850667 | G7: 0.15 | H7: 0.7385
A8: 0.2 | B8: 32 | C8: 7568.88 | D8: 2270.14 | E8: =D8/B8 -> 70.941875 | G8: 0.2 | H8: 0.7094
A9: 1.25 | B9: 1 | C9: 415.65 | D9: 122.97 | E9: =D9/B9 -> 122.97
A10: Grand Total | B10: 499 | C10: 131404.67 | D10: 38459.01

Sheet order status
A3: Row Labels | B3: Count of Order_ID | E3: profit margin
A4: Cancelled | B4: 99 | E4: =D4/B4 -> 0
A5: Completed | B5: 302 | E5: =D5/B5 -> 0
A6: Returned | B6: 98 | E6: =D6/B6 -> 0
A7: Grand Total | B7: 499

Sheet Customer id
A3: Row Labels | B3: Count of Order_ID | C3: Sum of Revenue | D3: Sum of Profit
A4: CUST0130 | B4: 7 | C4: 3149.69 | D4: 1128.62 | E4: =C4/B4 -> 449.95571
A5: CUST0113 | B5: 7 | C5: 2967.24 | D5: 932.24 | E5: =C5/B5 -> 423.89143
A6: CUST0053 | B6: 10 | C6: 3054.34 | D6: 896.98 | E6: =C6/B6 -> 305.434
A7: CUST0145 | B7: 5 | C7: 2246 | D7: 718.39 | E7: =C7/B7 -> 449.2
A8: CUST0063 | B8: 5 | C8: 1978.3 | D8: 641.3 | E8: =C8/B8 -> 395.66
A9: CUST0067 | B9: 4 | C9: 2174.82 | D9: 613.82 | E9: =C9/B9 -> 543.705
A10: CUST0098 | B10: 6 | C10: 1878.09 | D10: 596.93 | E10: =C10/B10 -> 313.015
A11: CUST0134 | B11: 4 | C11: 2063.03 | D11: 585.76 | E11: =C11/B11 -> 515.7575
A12: CUST0052 | B12: 4 | C12: 1619.97 | D12: 562.75 | E12: =C12/B12 -> 404.9925
A13: CUST0109 | B13: 7 | C13: 1809.58 | D13: 562.51 | E13: =C13/B13 -> 258.51143
A14: CUST0104 | B14: 7 | C14: 1605.32 | D14: 550.76 | E14: =C14/B14 -> 229.33143
A15: CUST0008 | B15: 5 | C15: 1617.21 | D15: 543.28 | E15: =C15/B15 -> 323.442
... A45: CUST0174 | B45: 4 | C45: 881.28 | D45: 319.1 | E45: =C45/B45 -> 220.32
A46: CUST0168 | B46: 3 | C46: 1079.85 | D46: 318.56
A47: CUST0027 | B47: 4 | C47: 936.96 | D47: 318.52
A48: CUST0118 | B48: 4 | C48: 962.03 | D48: 306.14
A49: CUST0082 | B49: 2 | C49: 741.83 | D49: 303.6
A50: CUST0062 | B50: 4 | C50: 1292.12 | D50: 300.7
A51: CUST0119 | B51: 3 | C51: 810.97 | D51: 296.58
A52: CUST0153 | B52: 3 | C52: 1027.51 | D52: 293.98
A53: CUST0093 | B53: 3 | C53: 1112.97 | D53: 293.91
A54: CUST0079 | B54: 3 | C54: 754.18 | D54: 285.28
A55: CUST0131 | B55: 4 | C55: 1009.85 | D55: 281.22
A56: CUST0172 | B56: 5 | C56: 1082.64 | D56: 276.46
A57: CUST0041 | B57: 3 | C57: 728.1 | D57: 265.49
... A168: Grand Total | B168: 499 | C168: 131404.67 | D168: 38459.01

Sheet products
A3: Row Labels | B3: Sum of Revenue
A4: Backpack | B4: 11205.22
A5: Storage Box | B5: 10565.42
A6: Sticky Notes | B6: 10459.34
A7: Notebook | B7: 10241.47
A8: Keyboard | B8: 9920.64
A9: Laptop Sleeve | B9: 8640.41
A10: Wireless Mouse | B10: 8621.32
A11: Cable Organizer | B11: 7977.46
A12: Office Chair | B12: 7457.14
A13: Water Bottle | B13: 7318.51
A14: Pen Set | B14: 7263.44
A15: Headphones | B15: 7233.03
... A20: Grand Total | B20: 131404.67

Sheet Dashboard
B1: E-Commerce Sales & Profitability Dashboard
B2: Total Revenue | D2: Total Orders | F2: Total Quantity | H2: AOV | J2: Recorded Profit | L2: Profit Margin
B3: =SUM(Cleaned_Data!J2:J500) -> 131404.67 | D3: =COUNTA(Cleaned_Data!A2:A500) -> 499 | F3: =SUM(Cleaned_Data!G2:G500) -> 1501 | H3: =B3/D3 -> 263.33601 | J3: =SUM(Cleaned_Data!L2:L500) -> 38459.01 | L3: =J3/B3 -> 0.29267613
